Workbook

Sheet Price Groups
A1: Price Groups & Assumptions
A3: Cost multiplier – exchange rate | B3: 15
A4: Cost multiplier – landed-cost factor | B4: 1.5
A5: Total cost multiplier (Shopify cost × this = EGP cost) | B5: =B3*B4 -> 22.5
A7: SAR→EGP rate used in current prices | B7: 12.5
A8: SAR→EGP rate today (22 Oct 2026) | B8: 14.74
A9: Currency increase (target average price increase) | B9: =B8/B7-1 -> 0.1792
A10: AlBaik meal cost at old rate (EGP) | B10: 370
A11: AlBaik meal NEW price (EGP) – all AlBaik items get the same % | B11: 669 | C11: =B11/580-1 -> 0.15344828 | D11: ← increase applied to every AlBaik item
A12: Group | B12: Name | C12: Increase % | D12: Assignment rule | E12: # Items | F12: Revenue (EGP, 2026) | G12: Revenue share | H12: Contribution
A13: 1 | B13: Group 1 | C13: 0.22 | D13: Margin < 25%, or slow movers (bottom 20% of revenue), or unsold items. AlBaik (cost rises with the riyal). | E13: =COUNTIFS('New Prices'!$R:$R,A13,'New Prices'!$C:$C,"<>Variant") -> 954 | F13: =SUMIFS('New Prices'!$K:$K,'New Prices'!$R:$R,A13,'New Prices'!$K:$K,">0") -> 4074378.4 | G13: =IF($F$18=0,0,F13/$F$18) -> 0.37380653 | H13: =G13*C13 -> 0.082237436
A14: 2 | B14: Group 2 | C14: 0.18 | D14: Core sellers (top 80% of revenue) with 25–40% margin, or no cost in Shopify | E14: =COUNTIFS('New Prices'!$R:$R,A14,'New Prices'!$C:$C,"<>Variant") -> 62 | F14: =SUMIFS('New Prices'!$K:$K,'New Prices'!$R:$R,A14,'New Prices'!$K:$K,">0") -> 1555790.6 | G14: =IF($F$18=0,0,F14/$F$18) -> 0.14273703 | H14: =G14*C14 -> 0.025692665
A15: 3 | B15: Group 3 | C15: 0.16 | D15: Core sellers (45–80% cumulative revenue) with margin ≥ 40% | E15: =COUNTIFS('New Prices'!$R:$R,A15,'New Prices'!$C:$C,"<>Variant") -> 153 | F15: =SUMIFS('New Prices'!$K:$K,'New Prices'!$R:$R,A15,'New Prices'!$K:$K,">0") -> 2655599.6 | G15: =IF($F$18=0,0,F15/$F$18) -> 0.24363974 | H15: =G15*C15 -> 0.038982358
A16: 4 | B16: Group 4 | C16: 0.15 | D16: Top revenue items (first 45% of revenue) with margin ≥ 40% | E16: =COUNTIFS('New Prices'!$R:$R,A16,'New Prices'!$C:$C,"<>Variant") -> 30 | F16: =SUMIFS('New Prices'!$K:$K,'New Prices'!$R:$R,A16,'New Prices'!$K:$K,">0") -> 2234854.5 | G16: =IF($F$18=0,0,F16/$F$18) -> 0.20503819 | H16: =G16*C16 -> 0.030755729
A17: 5 | B17: Group 5 | C17: 0.02 | D17: Price-sensitive best sellers: among 40 most-ordered, price < 50 EGP, margin ≥ 40% | E17: =COUNTIFS('New Prices'!$R:$R,A17,'New Prices'!$C:$C,"<>Variant") -> 23 | F17: =SUMIFS('New Prices'!$K:$K,'New Prices'!$R:$R,A17,'New Prices'!$K:$K,">0") -> 379075.38 | G17: =IF($F$18=0,0,F17/$F$18) -> 0.03477852 | H17: =G17*C17 -> 0.0006955704
A18: TOTAL | E18: =SUM(E13:E17) -> 1222 | F18: =SUM(F13:F17) -> 10899698 | G18: =SUM(G13:G17) -> 1
A21: Weighted average actual increase after rounding | B21: =IFERROR(SUMPRODUCT(('New Prices'!$R$5:$R$1281<>"-")*('New Prices'!$K$5:$K$1281>0)*'New Prices'!$K$5:$K$1281*'New Prices'!$V$5:$V$1281)/SUMPRODUCT(('New Prices'!$R$5:$R$1281<>"-")*('New Prices'!$K$5:$K$1281>0)*'New Prices'!$K$5:$K$1281),0) -> 0.17168805
A22: Target (currency increase) | B22: =B9 -> 0.1792
A23: Status | B23: =IF(B21>=B22,"✔ Target reached","✖ Below target – raise group %") -> ✖ Below target – raise group %
A25: Edit only the yellow cells. Every price in "New Prices" updates automatically.

Sheet New Prices
A1: Tamwenat Elzekrayat – New Prices by Price Group
A2: Sales period: 1 Jan – 22 Oct 2026 | Currency: EGP | Ranked by units sold | Current prices as in Shopify on 22 Oct 2026 (after wholesale fix)
A4: Rank | B4: Product | C4: Type | D4: Linked single / wholesale | E4: Status | F4: Units Sold | G4: Orders | H4: Gross Sales | I4: Discounts | J4: Returns | K4: Net Revenue | L4: % of Total Revenue | M4: Avg Net Price / Unit | N4: Current Price | O4: Cost in Shopify | P4: Unit Cost (EGP) | Q4: Current Margin | R4: Price Group | S4: Increase % | T4: New Price | U4: New Margin | V4: Actual Increase | W4: Reason
A5: 1 | B5: AlBaik meals | C5: Single | E5: Active | F5: 3695 | G5: 832 | H5: 1518355.2 | I5: -8260.48 | J5: -35101.2 | K5: =H5+I5+J5 -> 1474993.5 | L5: =IF($K$1282=0,0,K5/$K$1282) -> 0.12218616 | M5: =IF(F5<=0,0,K5/F5) -> 399.18633 | Q5: =IF(OR(N5="",P5=""),"",(N5-P5)/N5) | R5: 1 | S5: ='Price Groups'!$C$11 -> 0.15344828 | T5: =IF(OR(N5="",R5="-"),"",CEILING(ROUND(N5*(1+S5),2),IF(N5*(1+S5)<100,0.5,IF(N5*(1+S5)<1000,1,5)))) | U5: =IF(OR(T5="",P5=""),"",(T5-P5)/T5) | V5: =IFERROR(AVERAGE(V6:V31),0) -> 0.15512664 | W5: Custom increase set by user: meal 580 → 669 (+15.3%), same % on all AlBaik items. Cost 370 moves with the riyal → ≈436 today
B6: ↳ Spicy 4 pcs broasted chicken | C6: Variant | D6: AlBaik meals | K6: 0 | N6: 580 | P6: ='Price Groups'!$B$10*'Price Groups'!$B$8/'Price Groups'!$B$7 -> 436.304 | Q6: =IF(OR(N6="",P6=""),"",(N6-P6)/N6) -> 0.24775172 | R6: =R5 -> 1 | S6: ='Price Groups'!$C$11 -> 0.15344828 | T6: =IF(OR(N6="",R6="-"),"",CEILING(ROUND(N6*(1+S6),2),IF(N6*(1+S6)<100,0.5,IF(N6*(1+S6)<1000,1,5)))) -> 669 | U6: =IF(OR(T6="",P6=""),"",(T6-P6)/T6) -> 0.34782661 | V6: =IF(T6="",0,T6/N6-1) -> 0.15344828 | W6: Variant – same group as the product
B7: ↳ Regular 4 pcs broasted chicken | C7: Variant | D7: AlBaik meals | K7: 0 | N7: 580 | P7: ='Price Groups'!$B$10*'Price Groups'!$B$8/'Price Groups'!$B$7 -> 436.304 | Q7: =IF(OR(N7="",P7=""),"",(N7-P7)/N7) -> 0.24775172 | R7: =R5 -> 1 | S7: ='Price Groups'!$C$11 -> 0.15344828 | T7: =IF(OR(N7="",R7="-"),"",CEILING(ROUND(N7*(1+S7),2),IF(N7*(1+S7)<100,0.5,IF(N7*(1+S7)<1000,1,5)))) -> 669 | U7: =IF(OR(T7="",P7=""),"",(T7-P7)/T7) -> 0.34782661 | V7: =IF(T7="",0,T7/N7-1) -> 0.15344828 | W7: Variant – same group as the product
B8: ↳ Spicy 10 pcs mesahhab | C8: Variant | D8: AlBaik meals | K8: 0 | N8: 580 | P8: ='Price Groups'!$B$10*'Price Groups'!$B$8/'Price Groups'!$B$7 -> 436.304 | Q8: =IF(OR(N8="",P8=""),"",(N8-P8)/N8) -> 0.24775172 | R8: =R5 -> 1 | S8: ='Price Groups'!$C$11 -> 0.15344828 | T8: =IF(OR(N8="",R8="-"),"",CEILING(ROUND(N8*(1+S8),2),IF(N8*(1+S8)<100,0.5,IF(N8*(1+S8)<1000,1,5)))) -> 669 | U8: =IF(OR(T8="",P8=""),"",(T8-P8)/T8) -> 0.34782661 | V8: =IF(T8="",0,T8/N8-1) -> 0.15344828 | W8: Variant – same group as the product
B9: ↳ Regular 10 pcs mesahhab | C9: Variant | D9: AlBaik meals | K9: 0 | N9: 580 | P9: ='Price Groups'!$B$10*'Price Groups'!$B$8/'Price Groups'!$B$7 -> 436.304 | Q9: =IF(OR(N9="",P9=""),"",(N9-P9)/N9) -> 0.24775172 | R9: =R5 -> 1 | S9: ='Price Groups'!$C$11 -> 0.15344828 | T9: =IF(OR(N9="",R9="-"),"",CEILING(ROUND(N9*(1+S9),2),IF(N9*(1+S9)<100,0.5,IF(N9*(1+S9)<1000,1,5)))) -> 669 | U9: =IF(OR(T9="",P9=""),"",(T9-P9)/T9) -> 0.34782661 | V9: =IF(T9="",0,T9/N9-1) -> 0.15344828 | W9: Variant – same group as the product
B10: ↳ Big Baik regular | C10: Variant | D10: AlBaik meals | K10: 0 | N10: 420 | O10: 270 | P10: =O10*'Price Groups'!$B$8/'Price Groups'!$B$7 -> 318.384 | Q10: =IF(OR(N10="",P10=""),"",(N10-P10)/N10) -> 0.24194286 | R10: =R5 -> 1 | S10: ='Price Groups'!$C$11 -> 0.15344828 | T10: =IF(OR(N10="",R10="-"),"",CEILING(ROUND(N10*(1+S10),2),IF(N10*(1+S10)<100,0.5,IF(N10*(1+S10)<1000,1,5)))) -> 485 | U10: =IF(OR(T10="",P10=""),"",(T10-P10)/T10) -> 0.34353814 | V10: =IF(T10="",0,T10/N10-1) -> 0.1547619 | W10: Variant – same group as the product
B11: ↳ Big Baik regular + cheese | C11: Variant | D11: AlBaik meals | K11: 0 | N11: 480 | Q11: =IF(OR(N11="",P11=""),"",(N11-P11)/N11) | R11: =R5 -> 1 | S11: ='Price Groups'!$C$11 -> 0.15344828 | T11: =IF(OR(N11="",R11="-"),"",CEILING(ROUND(N11*(1+S11),2),IF(N11*(1+S11)<100,0.5,IF(N11*(1+S11)<1000,1,5)))) -> 554 | U11: =IF(OR(T11="",P11=""),"",(T11-P11)/T11) | V11: =IF(T11="",0,T11/N11-1) -> 0.15416667 | W11: Variant – same group as the product
B12: ↳ Big Baik spicy | C12: Variant | D12: AlBaik meals | K12: 0 | N12: 420 | O12: 270 | P12: =O12*'Price Groups'!$B$8/'Price Groups'!$B$7 -> 318.384 | Q12: =IF(OR(N12="",P12=""),"",(N12-P12)/N12) -> 0.24194286 | R12: =R5 -> 1 | S12: ='Price Groups'!$C$11 -> 0.15344828 | T12: =IF(OR(N12="",R12="-"),"",CEILING(ROUND(N12*(1+S12),2),IF(N12*(1+S12)<100,0.5,IF(N12*(1+S12)<1000,1,5)))) -> 485 | U12: =IF(OR(T12="",P12=""),"",(T12-P12)/T12) -> 0.34353814 | V12: =IF(T12="",0,T12/N12-1) -> 0.1547619 | W12: Variant – same group as the product
B13: ↳ Big Baik Spicy +cheese | C13: Variant | D13: AlBaik meals | K13: 0 | N13: 480 | Q13: =IF(OR(N13="",P13=""),"",(N13-P13)/N13) | R13: =R5 -> 1 | S13: ='Price Groups'!$C$11 -> 0.15344828 | T13: =IF(OR(N13="",R13="-"),"",CEILING(ROUND(N13*(1+S13),2),IF(N13*(1+S13)<100,0.5,IF(N13*(1+S13)<1000,1,5)))) -> 554 | U13: =IF(OR(T13="",P13=""),"",(T13-P13)/T13) | V13: =IF(T13="",0,T13/N13-1) -> 0.15416667 | W13: Variant – same group as the product
B14: ↳ extra cocktail sauce | C14: Variant | D14: AlBaik meals | K14: 0 | N14: 65 | O14: 25 | P14: =O14*'Price Groups'!$B$8/'Price Groups'!$B$7 -> 29.48 | Q14: =IF(OR(N14="",P14=""),"",(N14-P14)/N14) -> 0.54646154 | R14: =R5 -> 1 | S14: ='Price Groups'!$C$11 -> 0.15344828 | T14: =IF(OR(N14="",R14="-"),"",CEILING(ROUND(N14*(1+S14),2),IF(N14*(1+S14)<100,0.5,IF(N14*(1+S14)<1000,1,5)))) -> 75 | U14: =IF(OR(T14="",P14=""),"",(T14-P14)/T14) -> 0.60693333 | V14: =IF(T14="",0,T14/N14-1) -> 0.15384615 | W14: Variant – same group as the product
B15: ↳ extra garlic sauce | C15: Variant | D15: AlBaik meals | K15: 0 | N15: 65 | O15: 25 | P15: =O15*'Price Groups'!$B$8/'Price Groups'!$B$7 -> 29.48 | Q15: =IF(OR(N15="",P15=""),"",(N15-P15)/N15) -> 0.54646154 | R15: =R5 -> 1 | S15: ='Price Groups'!$C$11 -> 0.15344828 | T15: =IF(OR(N15="",R15="-"),"",CEILING(ROUND(N15*(1+S15),2),IF(N15*(1+S15)<100,0.5,IF(N15*(1+S15)<1000,1,5)))) -> 75 | U15: =IF(OR(T15="",P15=""),"",(T15-P15)/T15) -> 0.60693333 | V15: =IF(T15="",0,T15/N15-1) -> 0.15384615 | W15: Variant – same group as the product
B16: ↳ extra Mesahhab sauce | C16: Variant | D16: AlBaik meals | K16: 0 | N16: 65 | O16: 10 | P16: =O16*'Price Groups'!$B$8/'Price Groups'!$B$7 -> 11.792 | Q16: =IF(OR(N16="",P16=""),"",(N16-P16)/N16) -> 0.81858462 | R16: =R5 -> 1 | S16: ='Price Groups'!$C$11 -> 0.15344828 | T16: =IF(OR(N16="",R16="-"),"",CEILING(ROUND(N16*(1+S16),2),IF(N16*(1+S16)<100,0.5,IF(N16*(1+S16)<1000,1,5)))) -> 75 | U16: =IF(OR(T16="",P16=""),"",(T16-P16)/T16) -> 0.84277333 | V16: =IF(T16="",0,T16/N16-1) -> 0.15384615 | W16: Variant – same group as the product
B17: ↳ Shawarma sandwich with garlic sauce spaicy | C17: Variant | D17: AlBaik meals | K17: 0 | N17: 240 | Q17: =IF(OR(N17="",P17=""),"",(N17-P17)/N17) | R17: =R5 -> 1 | S17: ='Price Groups'!$C$11 -> 0.15344828 | T17: =IF(OR(N17="",R17="-"),"",CEILING(ROUND(N17*(1+S17),2),IF(N17*(1+S17)<100,0.5,IF(N17*(1+S17)<1000,1,5)))) -> 277 | U17: =IF(OR(T17="",P17=""),"",(T17-P17)/T17) | V17: =IF(T17="",0,T17/N17-1) -> 0.15416667 | W17: Variant – same group as the product
B18: ↳ Shawarma sandwich with garlic sauce | C18: Variant | D18: AlBaik meals | K18: 0 | N18: 240 | Q18: =IF(OR(N18="",P18=""),"",(N18-P18)/N18) | R18: =R5 -> 1 | S18: ='Price Groups'!$C$11 -> 0.15344828 | T18: =IF(OR(N18="",R18="-"),"",CEILING(ROUND(N18*(1+S18),2),IF(N18*(1+S18)<100,0.5,IF(N18*(1+S18)<1000,1,5)))) -> 277 | U18: =IF(OR(T18="",P18=""),"",(T18-P18)/T18) | V18: =IF(T18="",0,T18/N18-1) -> 0.15416667 | W18: Variant – same group as the product
B19: ↳ Regular Fish fillet burger sandwich | C19: Variant | D19: AlBaik meals | K19: 0 | N19: 210 | Q19: =IF(OR(N19="",P19=""),"",(N19-P19)/N19) | R19: =R5 -> 1 | S19: ='Price Groups'!$C$11 -> 0.15344828 | T19: =IF(OR(N19="",R19="-"),"",CEILING(ROUND(N19*(1+S19),2),IF(N19*(1+S19)<100,0.5,IF(N19*(1+S19)<1000,1,5)))) -> 243 | U19: =IF(OR(T19="",P19=""),"",(T19-P19)/T19) | V19: =IF(T19="",0,T19/N19-1) -> 0.15714286 | W19: Variant – same group as the product
B20: ↳ spicy Super baik Shrimp sandwich | C20: Variant | D20: AlBaik meals | K20: 0 | N20: 590 | Q20: =IF(OR(N20="",P20=""),"",(N20-P20)/N20) | R20: =R5 -> 1 | S20: ='Price Groups'!$C$11 -> 0.15344828 | T20: =IF(OR(N20="",R20="-"),"",CEILING(ROUND(N20*(1+S20),2),IF(N20*(1+S20)<100,0.5,IF(N20*(1+S20)<1000,1,5)))) -> 681 | U20: =IF(OR(T20="",P20=""),"",(T20-P20)/T20) | V20: =IF(T20="",0,T20/N20-1) -> 0.15423729 | W20: Variant – same group as the product
B21: ↳ Regular Fish fillet meal 6pcs | C21: Variant | D21: AlBaik meals | K21: 0 | N21: 570 | Q21: =IF(OR(N21="",P21=""),"",(N21-P21)/N21) | R21: =R5 -> 1 | S21: ='Price Groups'!$C$11 -> 0.15344828 | T21: =IF(OR(N21="",R21="-"),"",CEILING(ROUND(N21*(1+S21),2),IF(N21*(1+S21)<100,0.5,IF(N21*(1+S21)<1000,1,5)))) -> 658 | U21: =IF(OR(T21="",P21=""),"",(T21-P21)/T21) | V21: =IF(T21="",0,T21/N21-1) -> 0.15438596 | W21: Variant – same group as the product
B22: ↳ Regular fish fillet sandwich | C22: Variant | D22: AlBaik meals | K22: 0 | N22: 260 | Q22: =IF(OR(N22="",P22=""),"",(N22-P22)/N22) | R22: =R5 -> 1 | S22: ='Price Groups'!$C$11 -> 0.15344828 | T22: =IF(OR(N22="",R22="-"),"",CEILING(ROUND(N22*(1+S22),2),IF(N22*(1+S22)<100,0.5,IF(N22*(1+S22)<1000,1,5)))) -> 300 | U22: =IF(OR(T22="",P22=""),"",(T22-P22)/T22) | V22: =IF(T22="",0,T22/N22-1) -> 0.15384615 | W22: Variant – same group as the product
B23: ↳ spicy fish fillet sandwich | C23: Variant | D23: AlBaik meals | K23: 0 | N23: 280.8 | Q23: =IF(OR(N23="",P23=""),"",(N23-P23)/N23) | R23: =R5 -> 1 | S23: ='Price Groups'!$C$11 -> 0.15344828 | T23: =IF(OR(N23="",R23="-"),"",CEILING(ROUND(N23*(1+S23),2),IF(N23*(1+S23)<100,0.5,IF(N23*(1+S23)<1000,1,5)))) -> 324 | U23: =IF(OR(T23="",P23=""),"",(T23-P23)/T23) | V23: =IF(T23="",0,T23/N23-1) -> 0.15384615 | W23: Variant – same group as the product
B24: ↳ spicy Fish fillet meal 10pcs | C24: Variant | D24: AlBaik meals | K24: 0 | N24: 749 | Q24: =IF(OR(N24="",P24=""),"",(N24-P24)/N24) | R24: =R5 -> 1 | S24: ='Price Groups'!$C$11 -> 0.15344828 | T24: =IF(OR(N24="",R24="-"),"",CEILING(ROUND(N24*(1+S24),2),IF(N24*(1+S24)<100,0.5,IF(N24*(1+S24)<1000,1,5)))) -> 864 | U24: =IF(OR(T24="",P24=""),"",(T24-P24)/T24) | V24: =IF(T24="",0,T24/N24-1) -> 0.15353805 | W24: Variant – same group as the product
B25: ↳ 10 Piece spicy economy Shrimp Meal | C25: Variant | D25: AlBaik meals | K25: 0 | N25: 730 | Q25: =IF(OR(N25="",P25=""),"",(N25-P25)/N25) | R25: =R5 -> 1 | S25: ='Price Groups'!$C$11 -> 0.15344828 | T25: =IF(OR(N25="",R25="-"),"",CEILING(ROUND(N25*(1+S25),2),IF(N25*(1+S25)<100,0.5,IF(N25*(1+S25)<1000,1,5)))) -> 843 | U25: =IF(OR(T25="",P25=""),"",(T25-P25)/T25) | V25: =IF(T25="",0,T25/N25-1) -> 0.15479452 | W25: Variant – same group as the product
B26: ↳ Regular suber baik Shrimp sandwich | C26: Variant | D26: AlBaik meals | K26: 0 | N26: 595 | Q26: =IF(OR(N26="",P26=""),"",(N26-P26)/N26) | R26: =R5 -> 1 | S26: ='Price Groups'!$C$11 -> 0.15344828 | T26: =IF(OR(N26="",R26="-"),"",CEILING(ROUND(N26*(1+S26),2),IF(N26*(1+S26)<100,0.5,IF(N26*(1+S26)<1000,1,5)))) -> 687 | U26: =IF(OR(T26="",P26=""),"",(T26-P26)/T26) | V26: =IF(T26="",0,T26/N26-1) -> 0.15462185 | W26: Variant – same group as the product
B27: ↳ Albaik Shrimp Economy Meal 10 piece | C27: Variant | D27: AlBaik meals | K27: 0 | N27: 730 | Q27: =IF(OR(N27="",P27=""),"",(N27-P27)/N27) | R27: =R5 -> 1 | S27: ='Price Groups'!$C$11 -> 0.15344828 | T27: =IF(OR(N27="",R27="-"),"",CEILING(ROUND(N27*(1+S27),2),IF(N27*(1+S27)<100,0.5,IF(N27*(1+S27)<1000,1,5)))) -> 843 | U27: =IF(OR(T27="",P27=""),"",(T27-P27)/T27) | V27: =IF(T27="",0,T27/N27-1) -> 0.15479452 | W27: Variant – same group as the product
B28: ↳ 10 Piece Regular Jumbo Shrimp Meal | C28: Variant | D28: AlBaik meals | K28: 0 | N28: 890 | Q28: =IF(OR(N28="",P28=""),"",(N28-P28)/N28) | R28: =R5 -> 1 | S28: ='Price Groups'!$C$11 -> 0.15344828 | T28: =IF(OR(N28="",R28="-"),"",CEILING(ROUND(N28*(1+S28),2),IF(N28*(1+S28)<100,0.5,IF(N28*(1+S28)<1000,1,5)))) -> 1030 | U28: =IF(OR(T28="",P28=""),"",(T28-P28)/T28) | V28: =IF(T28="",0,T28/N28-1) -> 0.15730337 | W28: Variant – same group as the product
B29: ↳ Regular super baik grilled chicken | C29: Variant | D29: AlBaik meals | K29: 0 | N29: 560 | Q29: =IF(OR(N29="",P29=""),"",(N29-P29)/N29) | R29: =R5 -> 1 | S29: ='Price Groups'!$C$11 -> 0.15344828 | T29: =IF(OR(N29="",R29="-"),"",CEILING(ROUND(N29*(1+S29),2),IF(N29*(1+S29)<100,0.5,IF(N29*(1+S29)<1000,1,5)))) -> 646 | U29: =IF(OR(T29="",P29=""),"",(T29-P29)/T29) | V29: =IF(T29="",0,T29/N29-1) -> 0.15357143 | W29: Variant – same group as the product
B30: ↳ spicy super baik grilled chicken | C30: Variant | D30: AlBaik meals | K30: 0 | N30: 604.8 | Q30: =IF(OR(N30="",P30=""),"",(N30-P30)/N30) | R30: =R5 -> 1 | S30: ='Price Groups'!$C$11 -> 0.15344828 | T30: =IF(OR(N30="",R30="-"),"",CEILING(ROUND(N30*(1+S30),2),IF(N30*(1+S30)<100,0.5,IF(N30*(1+S30)<1000,1,5)))) -> 698 | U30: =IF(OR(T30="",P30=""),"",(T30-P30)/T30) | V30: =IF(T30="",0,T30/N30-1) -> 0.15410053 | W30: Variant – same group as the product
B31: ↳ ALBAIK Maamoul 2pieces | C31: Variant | D31: AlBaik meals | K31: 0 | N31: 19.99 | Q31: =IF(OR(N31="",P31=""),"",(N31-P31)/N31) | R31: =R5 -> 1 | S31: ='Price Groups'!$C$11 -> 0.15344828 | T31: =IF(OR(N31="",R31="-"),"",CEILING(ROUND(N31*(1+S31),2),IF(N31*(1+S31)<100,0.5,IF(N31*(1+S31)<1000,1,5)))) -> 23.5 | U31: =IF(OR(T31="",P31=""),"",(T31-P31)/T31) | V31: =IF(T31="",0,T31/N31-1) -> 0.17558779 | W31: Variant – same group as the product
A32: 2 | B32: Oman Chips spicy small pack | C32: Single | E32: Active | F32: 1414 | G32: 485 | H32: 67674.49 | I32: -401.61 | J32: -5567.47 | K32: =H32+I32+J32 -> 61705.41 | L32: =IF($K$1282=0,0,K32/$K$1282) -> 0.0051115798 | M32: =IF(F32<=0,0,K32/F32) -> 43.638904 | N32: 44.99 | O32: 0.77 | P32: =O32*'Price Groups'!$B$5 -> 17.325 | Q32: =IF(OR(N32="",P32=""),"",(N32-P32)/N32) -> 0.61491443 | R32: 5 | S32: =IF(R32="-",0,IFERROR(VLOOKUP(R32,'Price Groups'!$A$13:$C$17,3,FALSE()),0)) -> 0.02 | T32: =IF(OR(N32="",R32="-"),"",CEILING(ROUND(N32*(1+S32),2),IF(N32*(1+S32)<100,0.5,IF(N32*(1+S32)<1000,1,5)))) -> 46 | U32: =IF(OR(T32="",P32=""),"",(T32-P32)/T32) -> 0.62336957 | V32: =IF(T32="",0,T32/N32-1) -> 0.022449433 | W32: Price-sensitive best seller (frequent, cheap, high margin) – protect price image
A33: 3 | B33: special order | C33: - | E33: Active | F33: 1093 | G33: 143 | H33: 1140000 | I33: -63960.92 | J33: -46215 | K33: =H33+I33+J33 -> 1029824.1 | L33: =IF($K$1282=0,0,K33/$K$1282) -> 0.085309018 | M33: =IF(F33<=0,0,K33/F33) -> 942.19952 | N33: 1000 | Q33: =IF(OR(N33="",P33=""),"",(N33-P33)/N33) | R33: - | S33: =IF(R33="-",0,IFERROR(VLOOKUP(R33,'Price Groups'!$A$13:$C$17,3,FALSE()),0)) -> 0 | T33: =IF(OR(N33="",R33="-"),"",CEILING(ROUND(N33*(1+S33),2),IF(N33*(1+S33)<100,0.5,IF(N33*(1+S33)<1000,1,5)))) | U33: =IF(OR(T33="",P33=""),"",(T33-P33)/T33) | V33: =IF(T33="",0,T33/N33-1) -> 0 | W33: Not repriced – not a catalog product
A34: 4 | B34: Gandour Mastic Gum, One Piece, 2.7 Grams | C34: Single | E34: Active | F34: 1002 | G34: 90 | H34: 6942.1 | I34: -51.56 | J34: -702.4 | K34: =H34+I34+J34 -> 6188.14 | L34: =IF($K$1282=0,0,K34/$K$1282) -> 0.00051261585 | M34: =IF(F34<=0,0,K34/F34) -> 6.1757884 | N34: 12 | O34: 0.12 | P34: =O34*'Price Groups'!$B$5 -> 2.7 | Q34: =IF(OR(N34="",P34=""),"",(N34-P34)/N34) -> 0.775 | R34: 1 | S34: =IF(R34="-",0,IFERROR(VLOOKUP(R34,'Price Groups'!$A$13:$C$17,3,FALSE()),0)) -> 0.22 | T34: =IF(OR(N34="",R34="-"),"",CEILING(ROUND(N34*(1+S34),2),IF(N34*(1+S34)<100,0.5,IF(N34*(1+S34)<1000,1,5)))) -> 15 | U34: =IF(OR(T34="",P34=""),"",(T34-P34)/T34) -> 0.82 | V34: =IF(T34="",0,T34/N34-1) -> 0.25 | W34: Slow mover / long tail – low price sensitivity
A35: 5 | B35: Ghandour MESTEKA Gum 6 Pcs Pack | C35: Single | E35: Active | F35: 985 | G35: 323 | H35: 33223.77 | I35: -202.78 | J35: -4064.74 | K35: =H35+I35+J35 -> 28956.25 | L35: =IF($K$1282=0,0,K35/$K$1282) -> 0.0023986905 | M35: =IF(F35<=0,0,K35/F35) -> 29.397208 | N35: 30 | O35: 0.43 | P35: =O35*'Price Groups'!$B$5 -> 9.675 | Q35: =IF(OR(N35="",P35=""),"",(N35-P35)/N35) -> 0.6775 | R35: 5 | S35: =IF(R35="-",0,IFERROR(VLOOKUP(R35,'Price Groups'!$A$13:$C$17,3,FALSE()),0)) -> 0.02 | T35: =IF(OR(N35="",R35="-"),"",CEILING(ROUND(N35*(1+S35),2),IF(N35*(1+S35)<100,0.5,IF(N35*(1+S35)<1000,1,5)))) -> 31 | U35: =IF(OR(T35="",P35=""),"",(T35-P35)/T35) -> 0.68790323 | V35: =IF(T35="",0,T35/N35-1) -> 0.033333333 | W35: Price-sensitive best seller (frequent, cheap, high margin) – protect price image
A36: 6 | B36: Mirinda citrus | C36: Single | D36: Mirinda citrus 24pack | E36: Active | F36: 979 | G36: 439 | H36: 108001.82 | I36: -781.47 | J36: -12827.29 | K36: =H36+I36+J36 -> 94393.06 | L36: =IF($K$1282=0,0,K36/$K$1282) -> 0.0078193736 | M36: =IF(F36<=0,0,K36/F36) -> 96.417835 | N36: 95 | O36: 1.82 | P36: =O36*'Price Groups'!$B$5 -> 40.95 | Q36: =IF(OR(N36="",P36=""),"",(N36-P36)/N36) -> 0.56894737 | R36: 2 | S36: =IF(R36="-",0,IFERROR(VLOOKUP(R36,'Price Groups'!$A$13:$C$17,3,FALSE()),0)) -> 0.18 | T36: =IF(OR(N36="",R36="-"),"",CEILING(ROUND(N36*(1+S36),2),IF(N36*(1+S36)<100,0.5,IF(N36*(1+S36)<1000,1,5)))) -> 113 | U36: =IF(OR(T36="",P36=""),"",(T36-P36)/T36) -> 0.63761062 | V36: =IF(T36="",0,T36/N36-1) -> 0.18947368 | W36: Core seller, medium margin (40%)
A37: 7 | B37: (No product title – custom/manual items) | C37: - | E37: - | F37: 958 | G37: 549 | H37: 167784.68 | I37: -783.11 | J37: -24769.39 | K37: =H37+I37+J37 -> 142232.18 | L37: =IF($K$1282=0,0,K37/$K$1282) -> 0.011782292 | M37: =IF(F37<=0,0,K37/F37) -> 148.46783 | Q37: =IF(OR(N37="",P37=""),"",(N37-P37)/N37) | R37: - | S37: =IF(R37="-",0,IFERROR(VLOOKUP(R37,'Price Groups'!$A$13:$C$17,3,FALSE()),0)) -> 0 | T37: =IF(OR(N37="",R37="-"),"",CEILING(ROUND(N37*(1+S37),2),IF(N37*(1+S37)<100,0.5,IF(N37*(1+S37)<1000,1,5)))) | U37: =IF(OR(T37="",P37=""),"",(T37-P37)/T37) | V37: =IF(T37="",0,T37/N37-1) -> 0 | W37: Not repriced – not a catalog product
A38: 8 | B38: zamzam water 330ml | C38: Single | E38: Active | F38: 918 | G38: 300 | H38: 135592.18 | I38: -1177.3 | J38: -13082.09 | K38: =H38+I38+J38 -> 121332.79 | L38: =IF($K$1282=0,0,K38/$K$1282) -> 0.010051019 | M38: =IF(F38<=0,0,K38/F38) -> 132.1708 | N38: 149.99 | O38: 2.61 | P38: =O38*'Price Groups'!$B$5 -> 58.725 | Q38: =IF(OR(N38="",P38=""),"",(N38-P38)/N38) -> 0.6084739 | R38: 4 | S38: =IF(R38="-",0,IFERROR(VLOOKUP(R38,'Price Groups'!$A$13:$C$17,3,FALSE()),0)) -> 0.15 | T38: =IF(OR(N38="",R38="-"),"",CEILING(ROUND(N38*(1+S38),2),IF(N38*(1+S38)<100,0.5,IF(N38*(1+S38)<1000,1,5)))) -> 173 | U38: =IF(OR(T38="",P38=""),"",(T38-P38)/T38) -> 0.66054913 | V38: =IF(T38="",0,T38/N38-1) -> 0.15341023 | W38: Top revenue item with healthy margin
A39: 9 | B39: Zamzam water | C39: Single | E39: Active | F39: 831 | G39: 532 | H39: 645690.36 | I39: -10020.76 | J39: -42697.4 | K39: =H39+I39+J39 -> 592972.2 | L39: =IF($K$1282=0,0,K39/$K$1282) -> 0.049120891 | M39: =IF(F39<=0,0,K39/F39) -> 713.56462 | Q39: =IF(OR(N39="",P39=""),"",(N39-P39)/N39) | R39: 4 | S39: =IF(R39="-",0,IFERROR(VLOOKUP(R39,'Price Groups'!$A$13:$C$17,3,FALSE()),0)) -> 0.15 | T39: =IF(OR(N39="",R39="-"),"",CEILING(ROUND(N39*(1+S39),2),IF(N39*(1+S39)<100,0.5,IF(N39*(1+S39)<1000,1,5)))) | U39: =IF(OR(T39="",P39=""),"",(T39-P39)/T39) | V39: =IFERROR(AVERAGE(V40:V42),0) -> 0.1539267 | W39: Top revenue item with healthy margin
B40: ↳ 5 liters without cartoon | C40: Variant | D40: Zamzam water | K40: 0 | N40: 885 | O40: 13.8 | P40: =O40*'Price Groups'!$B$5 -> 310.5 | Q40: =IF(OR(N40="",P40=""),"",(N40-P40)/N40) -> 0.64915254 | R40: =R39 -> 4 | S40: =IF(R40="-",0,IFERROR(VLOOKUP(R40,'Price Groups'!$A$13:$C$17,3,FALSE()),0)) -> 0.15 | T40: =IF(OR(N40="",R40="-"),"",CEILING(ROUND(N40*(1+S40),2),IF(N40*(1+S40)<100,0.5,IF(N40*(1+S40)<1000,1,5)))) -> 1020 | U40: =IF(OR(T40="",P40=""),"",(T40-P40)/T40) -> 0.69558824 | V40: =IF(T40="",0,T40/N40-1) -> 0.15254237 | W40: Variant – same group as the product
B41: ↳ 5 liters with cartoon | C41: Variant | D41: Zamzam water | K41: 0 | N41: 950 | O41: 13.8 | P41: =O41*'Price Groups'!$B$5 -> 310.5 | Q41: =IF(OR(N41="",P41=""),"",(N41-P41)/N41) -> 0.67315789 | R41: =R39 -> 4 | S41: =IF(R41="-",0,IFERROR(VLOOKUP(R41,'Price Groups'!$A$13:$C$17,3,FALSE()),0)) -> 0.15 | T41: =IF(OR(N41="",R41="-"),"",CEILING(ROUND(N41*(1+S41),2),IF(N41*(1+S41)<100,0.5,IF(N41*(1+S41)<1000,1,5)))) -> 1095 | U41: =IF(OR(T41="",P41=""),"",(T41-P41)/T41) -> 0.71643836 | V41: =IF(T41="",0,T41/N41-1) -> 0.15263158 | W41: Variant – same group as the product
...

Sheet Notes
A1: How to read this file
A2: Ranking | B2: Same as the best-sellers report: units sold (1 Jan – 22 Oct 2026) descending, ties by net revenue. Products with no 2026 sales are listed at the end.
A3: Net Revenue | B3: Gross Sales + Discounts + Returns (discounts and returns are negative). Excludes shipping and tax.
A4: Unit Cost (EGP) | B4: Cost in Shopify × 15 × 1.5 (see Price Groups). AlBaik meals: 370 EGP × (14.74 / 12.5).
A5: Price Group | B5: Set per product from margin and revenue (rules on the Price Groups sheet). You can overwrite any group number 1–5 by hand.
A6: Wholesale | B6: Wholesale products (supplier tag contains جملة) always get the SAME group and % as their single item. Wholesale packs are max 15% cheaper per piece than the single (fixed in Shopify on 22 Oct 2026).
A7: New Price rounding | B7: Rounded UP: to 0.50 below 100 EGP, to 1 EGP below 1,000, to 5 EGP above.
A8: Variants | B8: Products with several variants (AlBaik, Zamzam, Altazaj, Lusine, Eid items) show sales on the product row and one row per variant (↳) with its own current and new price. All variants follow the product's group.
A9: Not repriced | B9: "special order" and the untitled custom-item line are not catalog products.
A10: Colours | B10: Blue = values from Shopify / your inputs. Black = formulas. Yellow cells on Price Groups are the levers to edit.
A11: Nothing changed in Shopify yet | B11: This file is a proposal. Prices in the store are unchanged until you approve.
