Workbook

Sheet Summary
A1: Price Changes Applied – 23/24 Oct 2026
A2: Store | B2: Tamwenat Elzekrayat (Shopify)
A3: Reason | B3: SAR→EGP 12.5 → 14.74 (+17.92%)
A4: Group increases | B4: G1 22% · G2 18% · G3 16% · G4 15% · G5 2% · Keef elmosafer = fixed prices
A6: Variants updated | B6: =COUNTA(Applied!A2:A1186) -> 1185
A7: Average change % (per item) | B7: =AVERAGE(Applied!H2:H1186) -> 0.20379785
A8: Excluded variants | B8: =COUNTA(Excluded!A2:A53) -> 52
A9: Skipped products | B9: =COUNTA(Skipped!A2:A21) -> 20
A10: Deleted products | B10: =COUNTA(Deleted!A2:A12) -> 11
A12: Rollback | B12: Old prices are in the Applied sheet and in reports/price_change_2026-10-23_rollback.json

Sheet Applied
A1: Product | B1: Variant | C1: Type | D1: Price Group | E1: Old Price (EGP) | F1: New Price (EGP) | G1: Change (EGP) | H1: Change % | I1: Reason
A2: Oman Chips spicy small pack | B2: - | C2: Single | D2: 5 | E2: 44.99 | F2: 46 | G2: =F2-E2 -> 1.01 | H2: =IF(E2=0,0,F2/E2-1) -> 0.022449433 | I2: Price-sensitive best seller (frequent, cheap, high margin) – protect price image
A3: Gandour Mastic Gum, One Piece, 2.7 Grams | B3: - | C3: Single | D3: 1 | E3: 12 | F3: 15 | G3: =F3-E3 -> 3 | H3: =IF(E3=0,0,F3/E3-1) -> 0.25 | I3: Slow mover / long tail – low price sensitivity
A4: Ghandour MESTEKA Gum 6 Pcs Pack | B4: - | C4: Single | D4: 5 | E4: 30 | F4: 31 | G4: =F4-E4 -> 1 | H4: =IF(E4=0,0,F4/E4-1) -> 0.033333333 | I4: Price-sensitive best seller (frequent, cheap, high margin) – protect price image
A5: Mirinda citrus | B5: - | C5: Single | D5: 2 | E5: 95 | F5: 113 | G5: =F5-E5 -> 18 | H5: =IF(E5=0,0,F5/E5-1) -> 0.18947368 | I5: Core seller, medium margin (40%)
A6: zamzam water 330ml | B6: - | C6: Single | D6: 4 | E6: 149.99 | F6: 173 | G6: =F6-E6 -> 23.01 | H6: =IF(E6=0,0,F6/E6-1) -> 0.15341023 | I6: Top revenue item with healthy margin
A7: Zamzam water | B7: 5 liters without cartoon | C7: Single | D7: 4 | E7: 885 | F7: 1020 | G7: =F7-E7 -> 135 | H7: =IF(E7=0,0,F7/E7-1) -> 0.15254237 | I7: Top revenue item with healthy margin
A8: Zamzam water | B8: 5 liters with cartoon | C8: Single | D8: 4 | E8: 950 | F8: 1095 | G8: =F8-E8 -> 145 | H8: =IF(E8=0,0,F8/E8-1) -> 0.15263158 | I8: Top revenue item with healthy margin
A9: Zamzam water | B9: 200 ml | C9: Single | D9: 4 | E9: 118.45 | F9: 137 | G9: =F9-E9 -> 18.55 | H9: =IF(E9=0,0,F9/E9-1) -> 0.15660616 | I9: Top revenue item with healthy margin
A10: Ulker choco sandwich | B10: - | C10: Single | D10: 3 | E10: 55.37 | F10: 64.5 | G10: =F10-E10 -> 9.13 | H10: =IF(E10=0,0,F10/E10-1) -> 0.16489074 | I10: Core seller with healthy margin
A11: Millionaire cheese corn | B11: - | C11: Single | D11: 5 | E11: 22 | F11: 22.5 | G11: =F11-E11 -> 0.5 | H11: =IF(E11=0,0,F11/E11-1) -> 0.022727273 | I11: Price-sensitive best seller (frequent, cheap, high margin) – protect price image
A12: Shani | B12: - | C12: Single | D12: 4 | E12: 99 | F12: 114 | G12: =F12-E12 -> 15 | H12: =IF(E12=0,0,F12/E12-1) -> 0.15151515 | I12: Top revenue item with healthy margin
A13: cheetos har nar | B13: - | C13: Single | D13: 5 | E13: 45 | F13: 46 | G13: =F13-E13 -> 1 | H13: =IF(E13=0,0,F13/E13-1) -> 0.022222222 | I13: Price-sensitive best seller (frequent, cheap, high margin) – protect price image
... A77: marami ketchup Flavor | B77: - | C77: Single | D77: 1 | E77: 23 | F77: 28.5 | G77: =F77-E77 -> 5.5 | H77: =IF(E77=0,0,F77/E77-1) -> 0.23913043 | I77: Slow mover / long tail – low price sensitivity
A78: keef elmosafer with cardamom 5 gm | B78: - | C78: Single | D78: Fixed | E78: 32 | F78: 29 | G78: =F78-E78 -> -3 | H78: =IF(E78=0,0,F78/E78-1) -> -0.09375 | I78: New price set by user – price drop due to high competition
A79: Heart lollipop (borgat) 1 pc. | B79: - | C79: Single | D79: 1 | E79: 14.16 | F79: 17.5 | G79: =F79-E79 -> 3.34 | H79: =IF(E79=0,0,F79/E79-1) -> 0.23587571 | I79: Slow mover / long tail – low price sensitivity
A80: Ring Candy Original | B80: - | C80: Single | D80: 1 | E80: 74.99 | F80: 91.5 | G80: =F80-E80 -> 16.51 | H80: =IF(E80=0,0,F80/E80-1) -> 0.22016269 | I80: Slow mover / long tail – low price sensitivity
A81: Saudi Indomie (red chili fried noodles) | B81: - | C81: Single | D81: 3 | E81: 82.39 | F81: 96 | G81: =F81-E81 -> 13.61 | H81: =IF(E81=0,0,F81/E81-1) -> 0.16518995 | I81: Core seller with healthy margin
A82: 7 days croissant chocolate | B82: - | C82: Single | D82: 3 | E82: 64.99 | F82: 75.5 | G82: =F82-E82 -> 10.51 | H82: =IF(E82=0,0,F82/E82-1) -> 0.16171719 | I82: Core seller with healthy margin
A83: oman chips Family Size | B83: - | C83: Single | D83: 4 | E83: 318.6 | F83: 367 | G83: =F83-E83 -> 48.4 | H83: =IF(E83=0,0,F83/E83-1) -> 0.15191463 | I83: Top revenue item with healthy margin
A84: chocolate safari | B84: - | C84: Single | D84: 3 | E84: 63.72 | F84: 74 | G84: =F84-E84 -> 10.28 | H84: =IF(E84=0,0,F84/E84-1) -> 0.16133082 | I84: Core seller with healthy margin
A85: Saudi Indomie (chicken curry) | B85: - | C85: Single | D85: 4 | E85: 63 | F85: 72.5 | G85: =F85-E85 -> 9.5 | H85: =IF(E85=0,0,F85/E85-1) -> 0.15079365 | I85: Top revenue item with healthy margin
A86: Saudi Indomie (green chili fried noodles) | B86: - | C86: Single | D86: 3 | E86: 79.73 | F86: 92.5 | G86: =F86-E86 -> 12.77 | H86: =IF(E86=0,0,F86/E86-1) -> 0.16016556 | I86: Core seller with healthy margin
A87: CRIC CRAC special flavor | B87: - | C87: Single | D87: 1 | E87: 32.77 | F87: 40 | G87: =F87-E87 -> 7.23 | H87: =IF(E87=0,0,F87/E87-1) -> 0.22062862 | I87: Slow mover / long tail – low price sensitivity
A88: Alrabee Orange Juice 125 Ml | B88: - | C88: Single | D88: 3 | E88: 49.99 | F88: 58 | G88: =F88-E88 -> 8.01 | H88: =IF(E88=0,0,F88/E88-1) -> 0.16023205 | I88: Core seller with healthy margin
A89: Elsaudia chocolate milk 200ml | B89: - | C89: Single | D89: 3 | E89: 80 | F89: 93 | G89: =F89-E89 -> 13 | H89: =IF(E89=0,0,F89/E89-1) -> 0.1625 | I89: Core seller with healthy margin
A90: indomie spicy fried noodles black | B90: - | C90: Single | D90: 3 | E90: 84.99 | F90: 99 | G90: =F90-E90 -> 14.01 | H90: =IF(E90=0,0,F90/E90-1) -> 0.16484292 | I90: Core seller with healthy margin
... A115: TOTTI Fruiti hearts | B115: - | C115: Single | D115: 1 | E115: 24.99 | F115: 30.5 | G115: =F115-E115 -> 5.51 | H115: =IF(E115=0,0,F115/E115-1) -> 0.2204882 | I115: Slow mover / long tail – low price sensitivity
A116: keef elmosafer with Saffron 30 gm | B116: - | C116: Single | D116: Fixed | E116: 135 | F116: 129 | G116: =F116-E116 -> -6 | H116: =IF(E116=0,0,F116/E116-1) -> -0.044444444 | I116: New price set by user – price drop due to high competition
A117: keef elmosafer with cardamom 30 gm | B117: - | C117: Single | D117: Fixed | E117: 139.99 | F117: 99 | G117: =F117-E117 -> -40.99 | H117: =IF(E117=0,0,F117/E117-1) -> -0.29280663 | I117: New price set by user – price drop due to high competition
A118: Fairco Hot Stix | B118: - | C118: Single | D118: 3 | E118: 149.99 | F118: 174 | G118: =F118-E118 -> 24.01 | H118: =IF(E118=0,0,F118/E118-1) -> 0.16007734 | I118: Core seller with healthy margin
A119: seno choco cream | B119: - | C119: Single | D119: 1 | E119: 16.09 | F119: 20 | G119: =F119-E119 -> 3.91 | H119: =IF(E119=0,0,F119/E119-1) -> 0.24300808 | I119: Slow mover / long tail – low price sensitivity
A120: marami BBQ flavor | B120: - | C120: Single | D120: 1 | E120: 24.99 | F120: 30.5 | G120: =F120-E120 -> 5.51 | H120: =IF(E120=0,0,F120/E120-1) -> 0.2204882 | I120: Slow mover / long tail – low price sensitivity
A121: Abu Qous (Heel Flavor) | B121: - | C121: Single | D121: 3 | E121: 140 | F121: 163 | G121: =F121-E121 -> 23 | H121: =IF(E121=0,0,F121/E121-1) -> 0.16428571 | I121: Core seller with healthy margin
A122: indian red crackers large pack | B122: - | C122: Single | D122: 3 | E122: 189.99 | F122: 221 | G122: =F122-E122 -> 31.01 | H122: =IF(E122=0,0,F122/E122-1) -> 0.16321912 | I122: Core seller with healthy margin
A123: Ice cream toy | B123: - | C123: Single | D123: 1 | E123: 35 | F123: 43 | G123: =F123-E123 -> 8 | H123: =IF(E123=0,0,F123/E123-1) -> 0.22857143 | I123: Slow mover / long tail – low price sensitivity
A124: borgat gummy raspderry & blackberry | B124: - | C124: Single | D124: 1 | E124: 23.62 | F124: 29 | G124: =F124-E124 -> 5.38 | H124: =IF(E124=0,0,F124/E124-1) -> 0.22777307 | I124: Slow mover / long tail – low price sensitivity
A125: Crispy ABC Family Ketchup | B125: - | C125: Single | D125: 3 | E125: 190 | F125: 221 | G125: =F125-E125 -> 31 | H125: =IF(E125=0,0,F125/E125-1) -> 0.16315789 | I125: Core seller with healthy margin
A126: Fairco Salted Sticks | B126: - | C126: Single | D126: 3 | E126: 190 | F126: 221 | G126: =F126-E126 -> 31 | H126: =IF(E126=0,0,F126/E126-1) -> 0.16315789 | I126: Core seller with healthy margin
A127: Pofak Oman family Cheese Flavour | B127: - | C127: Single | D127: 2 | E127: 94.99 | F127: 113 | G127: =F127-E127 -> 18.01 | H127: =IF(E127=0,0,F127/E127-1) -> 0.18959891 | I127: Core seller, medium margin (33%)
...

Sheet Excluded
A1: Product | B1: Variant | C1: Price (EGP, 22 Oct) | D1: Note
A2: AlBaik meals | B2: Spicy 4 pcs broasted chicken | C2: 580 | D2: Excluded by owner – price not changed
A3: AlBaik meals | B3: Regular 4 pcs broasted chicken | C3: 580 | D3: Excluded by owner – price not changed
A4: AlBaik meals | B4: Spicy 10 pcs mesahhab | C4: 580 | D4: Excluded by owner – price not changed
A5: AlBaik meals | B5: Regular 10 pcs mesahhab | C5: 580 | D5: Excluded by owner – price not changed
A6: AlBaik meals | B6: Big Baik regular | C6: 420 | D6: Excluded by owner – price not changed
A7: AlBaik meals | B7: Big Baik regular + cheese | C7: 480 | D7: Excluded by owner – price not changed
A8: AlBaik meals | B8: Big Baik spicy | C8: 420 | D8: Excluded by owner – price not changed
A9: AlBaik meals | B9: Big Baik Spicy +cheese | C9: 480 | D9: Excluded by owner – price not changed
A10: AlBaik meals | B10: extra cocktail sauce | C10: 65 | D10: Excluded by owner – price not changed
A11: AlBaik meals | B11: extra garlic sauce | C11: 65 | D11: Excluded by owner – price not changed
A12: AlBaik meals | B12: extra Mesahhab sauce | C12: 65 | D12: Excluded by owner – price not changed
A13: AlBaik meals | B13: Shawarma sandwich with garlic sauce spaicy | C13: 240 | D13: Excluded by owner – price not changed
... A53: Almarai mix berry juice | B53: - | C53: 410 | D53: Excluded by owner – price not changed

Sheet Skipped
A1: Product | B1: Price Group | C1: Price in Analysis | D1: Live Price (23 Oct) | E1: Planned New Price | F1: Reason
A2: tasali spicy small | B2: 3 | C2: 29.99 | D2: 24.99 | E2: 35 | F2: Price changed in Shopify after the 22-Oct analysis – review manually
A3: nescafe arabiana with safaran 1 pac 3 gm | B3: 1 | C3: 49.99 | D3: 30 | E3: 61 | F3: Price changed in Shopify after the 22-Oct analysis – review manually
A4: lays spicy mediam size 60g | B4: 2 | C4: 119.99 | D4: 60 | E4: 142 | F4: Price changed in Shopify after the 22-Oct analysis – review manually
A5: time candy | B5: 1 | C5: 8.22 | D5: 14 | E5: 10.5 | F5: Price changed in Shopify after the 22-Oct analysis – review manually
A6: Cake bar 7 days chocolate | B6: 1 | C6: 34.99 | D6: 29.99 | E6: 43 | F6: Price changed in Shopify after the 22-Oct analysis – review manually
A7: Chocolate Paste | B7: 1 | C7: 6.22 | D7: 16.15 | E7: 8 | F7: Price changed in Shopify after the 22-Oct analysis – review manually
A8: Saudi Indomie (baladi chicken) | B8: 3 | C8: 55 | D8: 75 | E8: 64 | F8: Price changed in Shopify after the 22-Oct analysis – review manually
A9: Marie Biscuits | B9: 1 | C9: 36 | D9: 49.99 | E9: 44 | F9: Price changed in Shopify after the 22-Oct analysis – review manually
A10: Saudi Indomie (baladi chicken) 5 pc | B10: 3 | C10: 250 | D10: 325 | E10: 290 | F10: Price changed in Shopify after the 22-Oct analysis – review manually
A11: abu kass rice 5kg | B11: 5 | C11: 850 | D11: 910 | E11: 867 | F11: Price changed in Shopify after the 22-Oct analysis – review manually
A12: Borgat Gummy bumble bear | B12: 1 | C12: 9.92 | D12: 19.95 | E12: 12.5 | F12: Price changed in Shopify after the 22-Oct analysis – review manually
A13: Miaw Miaw BBQ | B13: 1 | C13: 120 | D13: 100 | E13: 147 | F13: Price changed in Shopify after the 22-Oct analysis – review manually
... A18: golden potato spicy 65g | B18: 1 | C18: 149.99 | D18: 119.99 | E18: 183 | F18: Price changed in Shopify after the 22-Oct analysis – review manually
A19: millionaire corn curls | B19: 1 | C19: 11.05 | E19: 13.5 | F19: Product renamed in Shopify – not found
A20: Fine Rabea Leaf Tea 400 | B20: 3 | C20: 650 | E20: 754 | F20: Product renamed in Shopify – not found
A21: toffo deemah salted caramel | B21: 1 | C21: 350 | E21: 427 | F21: Product renamed in Shopify – not found

Sheet Deleted
A1: Product | B1: Price Group | C1: Last Price | D1: Planned New Price | E1: Status
A2: alameed turkish coffee without cardamom 250g | B2: 1 | C2: 575 | D2: 702 | E2: Was DRAFT/suspended – deleted from Shopify on 24 Oct (owner request)
A3: Al Ameed turkish Light Coffee without cardamom 250g | B3: 1 | C3: 574.99 | D3: 702 | E3: Was DRAFT/suspended – deleted from Shopify on 24 Oct (owner request)
A4: Al Ameed turkish black Coffee 250g | B4: 1 | C4: 574.99 | D4: 702 | E4: Was DRAFT/suspended – deleted from Shopify on 24 Oct (owner request)
A5: Al Ameed turkish black Coffee without cardamom 250g | B5: 1 | C5: 574.99 | D5: 702 | E5: Was DRAFT/suspended – deleted from Shopify on 24 Oct (owner request)
A6: alameed coffee french 250g | B6: 1 | C6: 574.99 | D6: 702 | E6: Was DRAFT/suspended – deleted from Shopify on 24 Oct (owner request)
A7: alameed coffee french hazelnut 250g | B7: 1 | C7: 599.99 | D7: 732 | E7: Was DRAFT/suspended – deleted from Shopify on 24 Oct (owner request)
A8: Al Ameed turkish Light Coffee 250g | B8: 1 | C8: 574.99 | D8: 702 | E8: Was DRAFT/suspended – deleted from Shopify on 24 Oct (owner request)
A9: alameed turkish coffee 250g | B9: 1 | C9: 575 | D9: 702 | E9: Was DRAFT/suspended – deleted from Shopify on 24 Oct (owner request)
A10: Al Ameed Decaf without cardamom Coffee 250g | B10: 1 | C10: 649.99 | D10: 793 | E10: Was DRAFT/suspended – deleted from Shopify on 24 Oct (owner request)
A11: alameed coffee french mistka 250g | B11: 1 | C11: 600 | D11: 732 | E11: Was DRAFT/suspended – deleted from Shopify on 24 Oct (owner request)
A12: alameed coffee french orangina 250g | B12: 1 | C12: 599.99 | D12: 732 | E12: Was DRAFT/suspended – deleted from Shopify on 24 Oct (owner request)
